<?xml version="1.0" ?>

<robot name="sawyer">

  <link name="base">
    <visual>
        <origin rpy="1.5708 0 -1.5708" xyz="0.26 0.345 -0.91488"/>
        <geometry>
          <mesh filename="sawyer_graphics/pedestal.obj"/>
        </geometry>
    </visual>
    <inertial>
        <origin rpy="0 0 0" xyz="0 0 0"/>
        <mass value="60.864"/>
        <inertia ixx="5.0636" ixy="0.0010342" ixz="0.802" iyy="6.0869" ifyz="0.0010531" izz="4.9619"/>
    </inertial>
  </link>

  <joint name="right_arm_mount" type="fixed">
    <origin rpy="0 0 0" xyz="0.0 0.0 0.0"/>
    <parent link="base"/>
    <child link="right_arm_base_link"/>
  </joint>

  <link name="right_arm_base_link">
    <inertial>
      <origin rpy="0 0 0" xyz="-0.0006241 -2.8025E-05 0.065404"/>
      <mass value="2.0687"/>
      <inertia ixx="0.0067599" ixy="-4.2024E-05" ixz="-6.1904E-07" iyy="0.0067877" iyz="1.5888E-05" izz="0.0074031"/>
    </inertial>
    <visual>
      <origin rpy="1.57 0 0" xyz="0 0 0"/>
      <geometry>
        <mesh filename="sawyer_graphics/base.obj"/>
      </geometry>
    </visual>
	<collision>
      <origin rpy="0 0 0" xyz="0 0 0.12"/>
      <geometry>
        <cylinder length="0.24" radius="0.08"/>
      </geometry>
    </collision>
  </link>

  <link name="right_l0">
    <inertial>
      <origin rpy="0 0 0" xyz="0.024366 0.010969 0.14363"/>
      <mass value="5.3213"/>
      <inertia ixx="0.053314" ixy="0.0047093" ixz="0.011734" iyy="0.057902" iyz="0.0080179" izz="0.023659"/>
    </inertial>
    <visual>
      <origin rpy="0 0 0" xyz="0 0 0"/>
      <geometry>
        <mesh filename="sawyer_graphics/l0.obj"/>
      </geometry>
    </visual>
	<collision>
      <origin rpy="0 0 0" xyz="0.081 0 0.237"/>
      <geometry>
        <sphere radius="0.07"/>
      </geometry>
    </collision>
  </link>

  <joint name="right_j0" type="revolute">
    <origin rpy="0 0 0" xyz="0 0 0.08"/>
    <parent link="right_arm_base_link"/>
    <child link="right_l0"/>
    <axis xyz="0 0 1"/>
    <limit effort="80.0" lower="-3.0503" upper="3.0503" velocity="1.74"/>
  </joint>

  <link name="head">
    <inertial>
      <origin rpy="0 0 0" xyz="0.0053207 -2.6549E-05 0.1021"/>
      <mass value="1.5795"/>
      <inertia ixx="0.011833" ixy="-4.4669E-06" ixz="4.9425E-05" iyy="0.0082709" iyz="4.2124E-07" izz="0.0049661"/>
    </inertial>
    <visual>
      <origin rpy="1.57 0 0" xyz="0 0 0"/>
      <geometry>
        <mesh filename="sawyer_graphics/head.obj"/>
      </geometry>
    </visual>
	<collision>
      <origin rpy="0 0 0" xyz="0 0 0.08"/>
      <geometry>
        <sphere radius="0.18"/>
      </geometry>
    </collision>
  </link>

  <joint name="head_pan" type="fixed"> <!-- Used to be revolute for head rotation -->
    <origin rpy="0 0 0" xyz="0 0 0.2965"/>
    <parent link="right_l0"/>
    <child link="head"/>
    <axis xyz="0 0 1"/>
    <limit effort="8" lower="-5.1477" upper="0.9559" velocity="1.8"/>
  </joint>

  <link name="right_l1">
    <inertial>
      <origin rpy="0 0 0" xyz="-0.0030849 -0.026811 0.092521"/>
      <mass value="4.505"/>
      <inertia ixx="0.022398" ixy="-0.00023986" ixz="-0.00029362" iyy="0.014613" iyz="-0.0060875" izz="0.017295"/>
    </inertial>
    <visual>
      <origin rpy="0 0 0" xyz="0 0 0"/>
      <geometry>
        <mesh filename="sawyer_graphics/l1.obj"/>
      </geometry>
    </visual>
	<collision>
      <origin rpy="0 0 0" xyz="0 0 0.1225"/>
      <geometry>
        <sphere radius="0.07"/>
      </geometry>
    </collision>
  </link>

  <joint name="right_j1" type="revolute">
    <origin rpy="-1.5708 -1.5708 0" xyz="0.081 0.05 0.237"/>
    <parent link="right_l0"/>
    <child link="right_l1"/>
    <axis xyz="0 0 1"/>
    <limit effort="80.0" lower="-3.8183" upper="2.2824" velocity="1.328"/>
  </joint>

  <link name="right_l2">
    <inertial>
      <origin rpy="0 0 0" xyz="-0.00016232 -0.015346 0.13445"/>
      <mass value="1.7251"/>
      <inertia ixx="0.025176" ixy="4.3031e-06" ixz="1.4564e-05" iyy="0.024982" iyz="-0.0033928" izz="0.0033798"/>
    </inertial>
    <visual>
      <origin rpy="1.57 0 0" xyz="0 0 0"/>
      <geometry>
        <mesh filename="sawyer_graphics/l2.obj"/>
      </geometry>
    </visual>
	<collision>
      <origin rpy="0 0 0" xyz="0 0 0.14"/>
      <geometry>
        <cylinder length="0.35" radius="0.06"/>
      </geometry>
    </collision>
  </link>

  <joint name="right_j2" type="revolute">
    <origin rpy="1.5708 0 0" xyz="0 -0.14 0.1425"/>
    <parent link="right_l1"/>
    <child link="right_l2"/>
    <axis xyz="0 0 1"/>
    <limit effort="40" lower="-3.0514" upper="3.0514" velocity="1.957"/>
  </joint>

  <link name="right_l3">
    <inertial>
      <origin rpy="0 0 0" xyz="-0.0046678 -0.028394 -0.083127"/>
      <mass value="2.4743"/>
      <inertia ixx="0.0099549" ixy="-1.7675e-05" ixz="0.00027521" iyy="0.0064248" iyz="0.0030853" izz="0.0067746"/>
    </inertial>
    <visual>
      <origin rpy="1.57 0 0" xyz="0 0 0"/>
      <geometry>
        <mesh filename="sawyer_graphics/l3.obj"/>
      </geometry>
    </visual>
	<collision>
      <origin rpy="0 0 0" xyz="0 -0.01 -0.12"/>
      <geometry>
        <sphere radius="0.06"/>
      </geometry>
    </collision>
  </link>

  <joint name="right_j3" type="revolute">
    <origin rpy="-1.5708 0 0" xyz="0 -0.042 0.26"/>
    <parent link="right_l2"/>
    <child link="right_l3"/>
    <axis xyz="0 0 1"/>
    <limit effort="40" lower="-3.0514" upper="3.0514" velocity="1.957"/>
  </joint>
  
  <link name="right_l4">
    <inertial>
      <origin rpy="0 0 0" xyz="-0.0027794 0.0076558 0.13273"/>
      <mass value="1.0433"/>
      <inertia ixx="0.012913" ixy="2.573e-05" ixz="0.00017705" iyy="0.012939" iyz="0.0011152" izz="0.0012405"/>
    </inertial>
    <visual>
      <origin rpy="1.57 0 0" xyz="0 0 0"/>
      <geometry>
        <mesh filename="sawyer_graphics/l4.obj"/>
      </geometry>
    </visual>
	<collision>
      <origin rpy="0 0 0" xyz="0 0 0.14"/>
      <geometry>
        <cylinder length="0.36" radius="0.045"/>
      </geometry>
    </collision>
  </link>

  <joint name="right_j4" type="revolute">
    <origin rpy="1.5708 0 0" xyz="0 -0.125 -0.1265"/>
    <parent link="right_l3"/>
    <child link="right_l4"/>
    <axis xyz="0 0 1"/>
    <limit effort="9" lower="-2.9842" upper="2.9842" velocity="3.485"/>
  </joint>

  <link name="right_l5">
    <inertial>
      <origin rpy="0 0 0" xyz="0.0062067 -0.024291 0.075564"/>
      <mass value="1.5343"/>
      <inertia ixx="0.0046072" ixy="0.00012002" ixz="5.3065e-05" iyy="0.0028725" iyz="-0.0011886" izz="0.003101"/>
    </inertial>
    <visual>
      <origin rpy="1.57 0 0" xyz="0 0 0"/>
      <geometry>
        <mesh filename="sawyer_graphics/l5.obj"/>
      </geometry>
    </visual>
	<collision>
      <origin rpy="0 0 0" xyz="0.01 0 0.09"/>
      <geometry>
        <sphere radius="0.06"/>
      </geometry>
    </collision>
  </link>

  <joint name="right_j5" type="revolute">
    <origin rpy="-1.5708 0 0" xyz="0 0.031 0.275"/>
    <parent link="right_l4"/>
    <child link="right_l5"/>
    <axis xyz="0 0 1"/>
    <limit effort="9" lower="-2.9842" upper="2.9842" velocity="3.485"/>
  </joint>

  <!-- if camera position on arm needed -->
  <!--
  <link name="right_hand_camera"/>

  <joint name="right_hand_camera" type="fixed">
    <origin rpy="0 1.5708 0" xyz="0.039552 -0.033 0.0695"/>
    <parent link="right_l5"/>
    <child link="right_hand_camera"/>
    <axis xyz="0 0 0"/>
  </joint>
  -->

  <link name="right_l6">
    <inertial>
      <origin rpy="0 0 0" xyz="-8.0726e-06 0.0085838 -0.0049566"/>
      <mass value="0.3292"/>
      <inertia ixx="0.00031105" ixy="1.4771e-06" ixz="-3.7074e-07" iyy="0.00021549" iyz="-8.4533e-06" izz="0.00035976"/>
    </inertial>
    <visual>
      <origin rpy="0 0 0" xyz="0 0 0"/>
      <geometry>
        <mesh filename="sawyer_graphics/l6.obj"/>
      </geometry>
    </visual>
	<collision>
      <origin rpy="0 0 0" xyz="0 0 -0.005"/>
      <geometry>
        <cylinder length="0.05" radius="0.065"/>
      </geometry>
    </collision>
  </link>

  <joint name="right_j6" type="revolute">
    <origin rpy="-1.5708 -0.17453 3.1416" xyz="0 -0.11 0.1053"/>
    <parent link="right_l5"/>
    <child link="right_l6"/>
    <axis xyz="0 0 1"/>
    <limit effort="9" lower="-4.7104" upper="4.7104" velocity="4.545"/>
  </joint>

  <!-- if camera position on head needed -->
  <!-- 
    <link name="head_camera"/>
  <joint name="head_camera" type="fixed">
    <origin rpy="-2.1293 0 -1.57079632679" xyz="0.0228027 0 0.216572"/>
    <parent link="head"/>
    <child link="head_camera"/>
    <axis xyz="0 0 0"/>
  </joint>
  -->

</robot>

